<?xml version="1.0" ?>
<!-- =================================================================================== -->
<!-- |    This document was autogenerated by xacro from panda_arm_hand.urdf.xacro      | -->
<!-- |    EDITING THIS FILE BY HAND IS NOT RECOMMENDED                                 | -->
<!-- =================================================================================== -->
<!-- =================================================================================== -->
<!-- |    This document was autogenerated by xacro from panda_arm_hand.urdf.xacro      | -->
<!-- |    EDITING THIS FILE BY HAND IS NOT RECOMMENDED                                 | -->
<!-- =================================================================================== -->
<!-- =================================================================================== -->
<!-- |    This document was autogenerated by xacro from panda_arm_hand.urdf.xacro      | -->
<!-- |    EDITING THIS FILE BY HAND IS NOT RECOMMENDED                                 | -->
<!-- =================================================================================== -->
<robot name="panda" xmlns:xacro="http://www.ros.org/wiki/xacro">
<material name="silver">
      <color rgba="0.700 0.700 0.700 1.000"/>
   </material>

   <material name="black">
      <color rgba="0.196 0.196 0.196 1.0"/>
   </material>

   <material name="white">
      <color rgba="1.0 1.0 1.0 1.0"/>
   </material>
   
  <link name="panda_link0">
  <inertial>
      <origin rpy="0 0 0" xyz="0 0 0.0"/>
       <mass value="2.9"/>
       <inertia ixx="0.1" ixy="0" ixz="0" iyy="0.1" iyz="0" izz="0.1"/>
    </inertial>
    <visual>
      <geometry>
        <mesh filename="package://franka_description/meshes/visual/link0.dae"/>
      </geometry>
    </visual>
    <collision>
      <geometry>
        <mesh filename="package://franka_description/meshes/collision/link0.stl"/>
      </geometry>
    </collision>
  </link>
  <link name="panda_link1">
  <inertial>
      <origin rpy="0 0 0" xyz="0 -0.04 -0.05"/>
       <mass value="2.7"/>
       <inertia ixx="0.1" ixy="0" ixz="0" iyy="0.1" iyz="0" izz="0.1"/>
    </inertial>
    <visual>
      <geometry>
        <mesh filename="package://franka_description/meshes/visual/link1.dae"/>
      </geometry>
    </visual>
    <collision>
      <geometry>
        <mesh filename="package://franka_description/meshes/collision/link1.stl"/>
      </geometry>
    </collision>
  </link>
  <joint name="panda_joint1" type="revolute">
    <safety_controller k_position="100.0" k_velocity="40.0" soft_lower_limit="-2.8973" soft_upper_limit="2.8973"/>
    <origin rpy="0 0 0" xyz="0 0 0.333"/>
    <parent link="panda_link0"/>
    <child link="panda_link1"/>
    <axis xyz="0 0 1"/>
    <limit effort="87" lower="-2.8973" upper="2.8973" velocity="2.1750"/>
  </joint>
  <link name="panda_link2">
  <inertial>
      <origin rpy="0 0 0" xyz="0 -0.04 0.06"/>
       <mass value="2.73"/>
       <inertia ixx="0.1" ixy="0" ixz="0" iyy="0.1" iyz="0" izz="0.1"/>
    </inertial>
    <visual>
      <geometry>
        <mesh filename="package://franka_description/meshes/visual/link2.dae"/>
      </geometry>
    </visual>
    <collision>
      <geometry>
        <mesh filename="package://franka_description/meshes/collision/link2.stl"/>
      </geometry>
    </collision>
  </link>
  <joint name="panda_joint2" type="revolute">
    <safety_controller k_position="100.0" k_velocity="40.0" soft_lower_limit="-1.7628" soft_upper_limit="1.7628"/>
    <origin rpy="-1.57079632679 0 0" xyz="0 0 0"/>
    <parent link="panda_link1"/>
    <child link="panda_link2"/>
    <axis xyz="0 0 1"/>
    <limit effort="87" lower="-1.7628" upper="1.7628" velocity="2.1750"/>
  </joint>
  <link name="panda_link3">
  <inertial>
      <origin rpy="0 0 0" xyz="0.01 0.01 -0.05"/>
       <mass value="2.04"/>
       <inertia ixx="0.1" ixy="0" ixz="0" iyy="0.1" iyz="0" izz="0.1"/>
    </inertial>
    <visual>
      <geometry>
        <mesh filename="package://franka_description/meshes/visual/link3.dae"/>
      </geometry>
    </visual>
    <collision>
      <geometry>
        <mesh filename="package://franka_description/meshes/collision/link3.stl"/>
      </geometry>
    </collision>
  </link>
  <joint name="panda_joint3" type="revolute">
    <safety_controller k_position="100.0" k_velocity="40.0" soft_lower_limit="-2.8973" soft_upper_limit="2.8973"/>
    <origin rpy="1.57079632679 0 0" xyz="0 -0.316 0"/>
    <parent link="panda_link2"/>
    <child link="panda_link3"/>
    <axis xyz="0 0 1"/>
    <limit effort="87" lower="-2.8973" upper="2.8973" velocity="2.1750"/>
  </joint>
  <link name="panda_link4">
  <inertial>
      <origin rpy="0 0 0" xyz="-0.03 0.03 0.02"/>
       <mass value="2.08"/>
       <inertia ixx="0.1" ixy="0" ixz="0" iyy="0.1" iyz="0" izz="0.1"/>
    </inertial>
    <visual>
      <geometry>
        <mesh filename="package://franka_description/meshes/visual/link4.dae"/>
      </geometry>
    </visual>
    <collision>
      <geometry>
        <mesh filename="package://franka_description/meshes/collision/link4.stl"/>
      </geometry>
    </collision>
  </link>
  <joint name="panda_joint4" type="revolute">
    <safety_controller k_position="100.0" k_velocity="40.0" soft_lower_limit="-3.0718" soft_upper_limit="-0.0698"/>
    <origin rpy="1.57079632679 0 0" xyz="0.0825 0 0"/>
    <parent link="panda_link3"/>
    <child link="panda_link4"/>
    <axis xyz="0 0 1"/>
    <limit effort="87" lower="-3.0718" upper="-0.0698" velocity="2.1750"/>
  </joint>
  <link name="panda_link5">
  <inertial>
      <origin rpy="0 0 0" xyz="0 0.04 -0.12"/>
       <mass value="3"/>
       <inertia ixx="0.1" ixy="0" ixz="0" iyy="0.1" iyz="0" izz="0.1"/>
    </inertial>
    <visual>
      <geometry>
        <mesh filename="package://franka_description/meshes/visual/link5.dae"/>
      </geometry>
    </visual>
    <collision>
      <geometry>
        <mesh filename="package://franka_description/meshes/collision/link5.stl"/>
      </geometry>
    </collision>
  </link>
  <joint name="panda_joint5" type="revolute">
    <safety_controller k_position="100.0" k_velocity="40.0" soft_lower_limit="-2.8973" soft_upper_limit="2.8973"/>
    <origin rpy="-1.57079632679 0 0" xyz="-0.0825 0.384 0"/>
    <parent link="panda_link4"/>
    <child link="panda_link5"/>
    <axis xyz="0 0 1"/>
    <limit effort="12" lower="-2.8973" upper="2.8973" velocity="2.6100"/>
  </joint>
  <link name="panda_link6">
  <inertial>
      <origin rpy="0 0 0" xyz="0.04 0 0"/>
       <mass value="1.3"/>
       <inertia ixx="0.1" ixy="0" ixz="0" iyy="0.1" iyz="0" izz="0.1"/>
    </inertial>
    <visual>
      <geometry>
        <mesh filename="package://franka_description/meshes/visual/link6.dae"/>
      </geometry>
    </visual>
    <collision>
      <geometry>
        <mesh filename="package://franka_description/meshes/collision/link6.stl"/>
      </geometry>
    </collision>
  </link>
  <joint name="panda_joint6" type="revolute">
    <safety_controller k_position="100.0" k_velocity="40.0" soft_lower_limit="-0.0175" soft_upper_limit="3.7525"/>
    <origin rpy="1.57079632679 0 0" xyz="0 0 0"/>
    <parent link="panda_link5"/>
    <child link="panda_link6"/>
    <axis xyz="0 0 1"/>
    <limit effort="12" lower="-0.0175" upper="3.7525" velocity="2.6100"/>
  </joint>
  <link name="panda_link7">
  <inertial>
      <origin rpy="0 0 0" xyz="0 0 0.08"/>
       <mass value=".2"/>
       <inertia ixx="0.1" ixy="0" ixz="0" iyy="0.1" iyz="0" izz="0.1"/>
    </inertial>
    <visual>
      <geometry>
        <mesh filename="package://franka_description/meshes/visual/link7.dae"/>
      </geometry>
    </visual>
    <collision>
      <geometry>
        <mesh filename="package://franka_description/meshes/collision/link7.stl"/>
      </geometry>
    </collision>
  </link>
  <joint name="panda_joint7" type="revolute">
    <safety_controller k_position="100.0" k_velocity="40.0" soft_lower_limit="-2.8973" soft_upper_limit="2.8973"/>
    <origin rpy="1.57079632679 0 0" xyz="0.088 0 0"/>
    <parent link="panda_link6"/>
    <child link="panda_link7"/>
    <axis xyz="0 0 1"/>
    <limit effort="12" lower="-2.8973" upper="2.8973" velocity="2.6100"/>
  </joint>

   <!-- setting attachment point for EEF models -->
  <!-- <link name="panda_link8">
  	 <inertial>
      <origin rpy="0 0 0" xyz="0 0 0"/>
       <mass value="0.0"/>
       <inertia ixx="0.1" ixy="0" ixz="0" iyy="0.1" iyz="0" izz="0.1"/>
    </inertial>
  </link>  -->
  <link name="panda_link8"/>

  <joint name="panda_joint8" type="fixed">
    <origin rpy="0 0 0" xyz="0 0 0.107"/>
    <parent link="panda_link7"/>
    <child link="panda_link8"/>
    <axis xyz="0 0 0"/>
  </joint>
  
   <!-- this is for original panda hand -->
  <!-- <joint name="panda_hand_joint" type="fixed">
    <parent link="panda_link8"/>
    <child link="offset_link"/>
    <origin rpy="0 0 -0.785398163397" xyz="0 0 0"/>
  </joint> -->

<!--################################################
  ########              gripper                  #####
  ####################################################-->
  <joint name="delto_base_joint" type="fixed">
    <parent link="panda_link8"/>
    <child link="delto_base_link"/>
    <origin rpy="0 0 0" xyz="0 0 0.0502"/>
  </joint>


  <link name="delto_base_link">

      <inertial>
         <origin xyz="0.00045499721796859983 -2.051648304165415e-06 -0.15218562175888181" rpy="5.671320207730568e-06 0.0032948722942074404 -0.00044870150924543735"/>
         <mass value="0.370"/>
         <inertia ixx="0.0009935903471030175" iyy="0.000980251548061173" izz="0.0003178199035240808" ixy="0" ixz="0" iyz="0"/>
      </inertial>

      <visual>
         <origin xyz="0.00045499721796859983 -2.051648304165415e-06 -0.05218562175888181" rpy="5.671320207730568e-06 0.0032948722942074404 -0.00044870150924543735"/>
         <geometry>
            <mesh filename="meshes/delto_base_link.stl"/>
         </geometry>
         <material name="black"/>
      </visual>

      <collision>
         <origin xyz="0.00045499721796859983 -2.051648304165415e-06 -0.05218562175888181" rpy="5.671320207730568e-06 0.0032948722942074404 -0.00044870150924543735"/>
         <geometry>
            <mesh filename="meshes/delto_base_link.stl"/>
         </geometry>
      </collision>

   </link>

   <link name="F1_01">

      <inertial>
         <origin xyz="0.0003906 3.121e-08 -0.014" rpy= "-0.17662368646091148 -1.9303231388878572e-06 1.5707855116626381"/>
         <mass value="0.061"/>
         <inertia ixx="1.924000000025899e-05" iyy="1.709411627342488e-05" izz="5.9478837263161295e-06" ixy="0" ixz="0" iyz="0"/>
      </inertial>

      <visual>
         <origin xyz="0.0018977016221143523 -1.0017682763976983e-06 -0.022983822146236326" rpy="-0.1443920950720977 1.9855029389503898e-05 1.5709191233325221"/>
         <geometry>
            <mesh filename="meshes/link_01.stl"/>
         </geometry>
         <material name="black"/>
      </visual>
      
      <collision>
         <origin xyz="0.0018977016221143523 -1.0017682763976983e-06 -0.022983822146236326" rpy="-0.1443920950720977 1.9855029389503898e-05 1.5709191233325221"/>
         <geometry>
            <mesh filename="meshes/link_01.stl"/>
         </geometry>
      </collision> 

   </link>

   <link name="F1_02">

      <inertial>
         <origin xyz="0.01 3.444e-06 0.016" rpy="-0.0036890516412144943 0.31688564121750695 -0.0027736178951144786"/>
         <mass value="0.025"/>
         <inertia ixx="7.164797732610912e-06" iyy="6.31301833122199e-06" izz="3.274183936167101e-06" ixy="0" ixz="0" iyz="0"/>
      </inertial>

      <visual>
         <origin xyz="0.010322007813576017 0.000267674195662055 0.013590600703218703" rpy="-0.03118104794815292 0.3757385725887219 -0.024334342208719002"/>
         <geometry>
            <mesh filename="meshes/link_02.stl"/>
         </geometry>
         <material name="black"/>
      </visual>

      <collision>
         <origin xyz="0.010322007813576017 0.000267674195662055 0.013590600703218703" rpy="-0.03118104794815292 0.3757385725887219 -0.024334342208719002"/>
         <geometry>
            <mesh filename="meshes/link_02.stl"/>
         </geometry>
      </collision>
   </link>

   <link name="F1_03">

      <inertial>
         <origin xyz="0.014 -0.0004527 -3.953e-05" rpy="1.5651066808062148 -0.0008576993469346927 1.5562600280492769"/>
         <mass value="0.051"/>
         <inertia ixx="1.6912201686125405e-05" iyy="1.4940271596370447e-05" izz="6.505526717504149e-06" ixy="0" ixz="0" iyz="0"/>
      </inertial>

      <visual>
         <origin xyz="0.019034639558839914 -0.0007611783816217545 0.00015734818842133856" rpy="1.5405533073968862 -0.0023628127138719535 1.5994547590929262"/>
         <geometry>
            <mesh filename="meshes/link_03.stl"/>
         </geometry>
         <material name="black"/>
      </visual>

      <collision>
         <origin xyz="0.019034639558839914 -0.0007611783816217545 0.00015734818842133856" rpy="1.5405533073968862 -0.0023628127138719535 1.5994547590929262"/>
         <geometry>
            <mesh filename="meshes/link_03.stl"/>
         </geometry>
      </collision>

   </link>

   <link name="F1_04">
      <inertial>
         <origin xyz="0.012 -0.0002269 -4.676e-05" rpy="1.5668480451228681 -0.0008686188531681349 1.5829731507939977"/>
         <mass value="0.058"/>
         <inertia ixx="1.0860820276783573e-05" iyy="9.902070548178027e-06" izz="5.330109175038405e-06" ixy="0" ixz="0" iyz="0"/>
      </inertial>

      <visual>
         <origin xyz="0.011992289866897352 -0.0007726988011287212 -5.201111709052532e-06" rpy="1.5745317514920234 0.003601150001683928 1.6650413701206925"/>
         <geometry>
            <mesh filename="meshes/link_04.stl"/>
         </geometry>
         <material name="black"/>
      </visual>

      <collision>
         <origin xyz="0.011992289866897352 -0.0007726988011287212 -5.201111709052532e-06" rpy="1.5745317514920234 0.003601150001683928 1.6650413701206925"/>
         <geometry>
            <mesh filename="meshes/link_04.stl"/>
         </geometry>
      </collision>

   </link>

   <link name="F1_TIP">
      <inertial>
         <origin xyz="0.045 -0.000436 -7.22e-08" rpy="1.5708008179564292 -3.695361794919805e-05 1.5210948927815267"/>
         <mass value="0.013"/>
         <inertia ixx="1.5965708653714455e-06" iyy="1.2999999996018677e-06" izz="9.60129135026688e-07" ixy="0" ixz="0" iyz="0"/>
      </inertial>

      <visual>
         <origin xyz="0.044959448417087294 -0.0004226309811080281 2.3018946871860735e-07" rpy="1.5708745579876908 -1.019986385419891e-05 1.5204133624130758"/>
         <geometry>
            <mesh filename="meshes/link_tip_high.stl"/>
         </geometry>
         <material name="white"/>
      </visual>

      <collision>
         <origin xyz="0.044959448417087294 -0.0004226309811080281 2.3018946871860735e-07" rpy="1.5708745579876908 -1.019986385419891e-05 1.5204133624130758"/>
         <geometry>
            <mesh filename="meshes/link_tip_high.stl"/>
         </geometry>
      </collision>
   </link>

   <link name="F2_01">
      <inertial>
         <origin xyz="0.0003906 3.121e-08 -0.014" rpy="-0.17662368646091148 -1.9303231388878572e-06 1.5707855116626381"/>
         <mass value="0.061"/>
         <inertia ixx="1.924000000025899e-05" iyy="1.709411627342488e-05" izz="5.9478837263161295e-06" ixy="0" ixz="0" iyz="0"/>
      </inertial>

      <visual>
         <origin xyz="0.0018977016221143523 -1.0017682763976983e-06 -0.022983822146236326" rpy="-0.1443920950720977 1.9855029389503898e-05 1.5709191233325221"/>
         <geometry>
            <mesh filename="meshes/link_01.stl"/>
         </geometry>
         <material name="black"/>
      </visual>

      <collision>
         <origin xyz="0.0018977016221143523 -1.0017682763976983e-06 -0.022983822146236326" rpy="-0.1443920950720977 1.9855029389503898e-05 1.5709191233325221"/>
         <geometry>
            <mesh filename="meshes/link_01.stl"/>
         </geometry>
      </collision>

   </link>

   <link name="F2_02">
      <inertial>
         <origin xyz="0.01 3.444e-06 0.016" rpy="-0.0036890516412144943 0.31688564121750695 -0.0027736178951144786"/>
         <mass value="0.025"/>
         <inertia ixx="7.164797732610912e-06" iyy="6.31301833122199e-06" izz="3.274183936167101e-06" ixy="0" ixz="0" iyz="0"/>
      </inertial>

      <visual>
         <origin xyz="0.010322007813576017 0.000267674195662055 0.013590600703218703" rpy="-0.03118104794815292 0.3757385725887219 -0.024334342208719002"/>
         <geometry>
            <mesh filename="meshes/link_02.stl"/>
         </geometry>
         <material name="black"/>
      </visual>

      <collision>
         <origin xyz="0.010322007813576017 0.000267674195662055 0.013590600703218703" rpy="-0.03118104794815292 0.3757385725887219 -0.024334342208719002"/>
         <geometry>
            <mesh filename="meshes/link_02.stl"/>
         </geometry>
      </collision>

   </link>

   <link name="F2_03">
   
      <inertial>
         <origin xyz="0.014 -0.0004527 -3.953e-05" rpy="1.5651066808062148 -0.0008576993469346927 1.5562600280492769"/>
         <mass value="0.051"/>
         <inertia ixx="1.6912201686125405e-05" iyy="1.4940271596370447e-05" izz="6.505526717504149e-06" ixy="0" ixz="0" iyz="0"/>
      </inertial>

      <visual>
         <origin xyz="0.019034639558839914 -0.0007611783816217545 0.00015734818842133856" rpy="1.5405533073968862 -0.0023628127138719535 1.5994547590929262"/>
         <geometry>
            <mesh filename="meshes/link_03.stl"/>
         </geometry>
         <material name="black"/>
      </visual>


      <collision>
         <origin xyz="0.019034639558839914 -0.0007611783816217545 0.00015734818842133856" rpy="1.5405533073968862 -0.0023628127138719535 1.5994547590929262"/>
         <geometry>
            <mesh filename="meshes/link_03.stl"/>
         </geometry>
      </collision>

   </link>

   <link name="F2_04">
      <inertial>
         <origin xyz="0.012 -0.0002269 -4.676e-05" rpy="1.5668480451228681 -0.0008686188531681349 1.5829731507939977"/>
         <mass value="0.058"/>
         <inertia ixx="1.0860820276783573e-05" iyy="9.902070548178027e-06" izz="5.330109175038405e-06" ixy="0" ixz="0" iyz="0"/>
      </inertial>

      <visual>
         <origin xyz="0.011992289866897352 -0.0007726988011287212 -5.201111709052532e-06" rpy="1.5745317514920234 0.003601150001683928 1.6650413701206925"/>
         <geometry>
            <mesh filename="meshes/link_04.stl"/>
         </geometry>
         <material name="black"/>
      </visual>

      <collision>
         <origin xyz="0.011992289866897352 -0.0007726988011287212 -5.201111709052532e-06" rpy="1.5745317514920234 0.003601150001683928 1.6650413701206925"/>
         <geometry>
            <mesh filename="meshes/link_04.stl"/>
         </geometry>
      </collision>
   </link>


   <link name="F2_TIP">
      <inertial>
         <origin xyz="0.045 -0.000436 -7.22e-08" rpy="1.5708008179564292 -3.695361794919805e-05 1.5210948927815267"/>
         <mass value="0.013"/>
         <inertia ixx="1.5965708653714455e-06" iyy="1.2999999996018677e-06" izz="9.60129135026688e-07" ixy="0" ixz="0" iyz="0"/>
      </inertial>

      <visual>
         <origin xyz="0.044959448417087294 -0.0004226309811080281 2.3018946871860735e-07" rpy="1.5708745579876908 -1.019986385419891e-05 1.5204133624130758"/>
         <geometry>
            <mesh filename="meshes/link_tip_high.stl"/>
         </geometry>
         <material name="white"/>
      </visual>

      <collision>
      <origin xyz="0.044959448417087294 -0.0004226309811080281 2.3018946871860735e-07" rpy="1.5708745579876908 -1.019986385419891e-05 1.5204133624130758"/>
         <geometry>
            <mesh filename="meshes/link_tip_high.stl"/>
         </geometry>
      </collision>
   </link>

   <link name="F3_01">
      <inertial>
         <origin xyz="0.0003906 3.121e-08 -0.014" rpy="-0.17662368646091148 -1.9303231388878572e-06 1.5707855116626381"/>
         <mass value="0.061"/>
         <inertia ixx="1.924000000025899e-05" iyy="1.709411627342488e-05" izz="5.9478837263161295e-06" ixy="0" ixz="0" iyz="0"/>
      </inertial>

      <visual>
         <origin xyz="0.0018977016221143523 -1.0017682763976983e-06 -0.022983822146236326" rpy="-0.1443920950720977 1.9855029389503898e-05 1.5709191233325221"/>
         <geometry>
            <mesh filename="meshes/link_01.stl"/>
         </geometry>
         <material name="black"/>
      </visual>

      <collision>
      <origin xyz="0.0018977016221143523 -1.0017682763976983e-06 -0.022983822146236326" rpy="-0.1443920950720977 1.9855029389503898e-05 1.5709191233325221"/>
         <geometry>
            <mesh filename="meshes/link_01.stl"/>
         </geometry>
      </collision>
   </link>
   
   <link name="F3_02">
      <inertial>
         <origin xyz="0.01 3.444e-06 0.016" rpy="-0.0036890516412144943 0.31688564121750695 -0.0027736178951144786"/>
         <mass value="0.025"/>
         <inertia ixx="7.164797732610912e-06" iyy="6.31301833122199e-06" izz="3.274183936167101e-06" ixy="0" ixz="0" iyz="0"/>
      </inertial>
      <visual>
         <origin xyz="0.010322007813576017 0.000267674195662055 0.013590600703218703" rpy="-0.03118104794815292 0.3757385725887219 -0.024334342208719002"/>
         <geometry>
            <mesh filename="meshes/link_02.stl"/>
         </geometry>
         <material name="black"/>
      </visual>

      <collision>
         <origin xyz="0.010322007813576017 0.000267674195662055 0.013590600703218703" rpy="-0.03118104794815292 0.3757385725887219 -0.024334342208719002"/>
         <geometry>
            <mesh filename="meshes/link_02.stl"/>
         </geometry>
      </collision>

   </link>

   <link name="F3_03">
      <inertial>
         <origin xyz="0.014 -0.0004527 -3.953e-05" rpy="1.5651066808062148 -0.0008576993469346927 1.5562600280492769"/>
         <mass value="0.051"/>
         <inertia ixx="1.6912201686125405e-05" iyy="1.4940271596370447e-05" izz="6.505526717504149e-06" ixy="0" ixz="0" iyz="0"/>
      </inertial>
      <visual>
         <origin xyz="0.019034639558839914 -0.0007611783816217545 0.00015734818842133856" rpy="1.5405533073968862 -0.0023628127138719535 1.5994547590929262"/>
         <geometry>
            <mesh filename="meshes/link_03.stl"/>
         </geometry>
         <material name="black"/>
      </visual>

      <collision>
         <origin xyz="0.019034639558839914 -0.0007611783816217545 0.00015734818842133856" rpy="1.5405533073968862 -0.0023628127138719535 1.5994547590929262"/>
         <geometry>
            <mesh filename="meshes/link_03.stl"/>
         </geometry>
      </collision>

   </link>

   <link name="F3_04">
      <inertial>
         <origin xyz="0.012 -0.0002269 -4.676e-05" rpy="1.5668480451228681 -0.0008686188531681349 1.5829731507939977"/>
         <mass value="0.058"/>
         <inertia ixx="1.0860820276783573e-05" iyy="9.902070548178027e-06" izz="5.330109175038405e-06" ixy="0" ixz="0" iyz="0"/>
      </inertial>
      <visual>
         <origin xyz="0.011992289866897352 -0.0007726988011287212 -5.201111709052532e-06" rpy="1.5745317514920234 0.003601150001683928 1.6650413701206925"/>
         <geometry>
            <mesh filename="meshes/link_04.stl"/>
         </geometry>
         <material name="black"/>
      </visual>

      <collision>
      <origin xyz="0.011992289866897352 -0.0007726988011287212 -5.201111709052532e-06" rpy="1.5745317514920234 0.003601150001683928 1.6650413701206925"/>
         <geometry>
            <mesh filename="meshes/link_04.stl"/>
         </geometry>
      </collision>

   </link>


   <link name="F3_TIP">
      <inertial>
         <origin xyz="0.045 -0.000436 -7.22e-08" rpy="1.5708008179564292 -3.695361794919805e-05 1.5210948927815267"/>
         <mass value="0.013"/>
         <inertia ixx="1.5965708653714455e-06" iyy="1.2999999996018677e-06" izz="9.60129135026688e-07" ixy="0" ixz="0" iyz="0"/>
      </inertial>
      <visual>
         <origin xyz="0.044959448417087294 -0.0004226309811080281 2.3018946871860735e-07" rpy="1.5708745579876908 -1.019986385419891e-05 1.5204133624130758"/>
         <geometry>
            <mesh filename="meshes/link_tip_high.stl"/>
         </geometry>
         <material name="white"/>
      </visual>

      <collision>
         <origin xyz="0.044959448417087294 -0.0004226309811080281 2.3018946871860735e-07" rpy="1.5708745579876908 -1.019986385419891e-05 1.5204133624130758"/>
         <geometry>
            <mesh filename="meshes/link_tip_high.stl"/>
         </geometry>
      </collision>

   </link>

   <!--Joint -->

   <joint name = "F1M1" type = "revolute">
      <origin xyz="0.0265 0.0 0.0" rpy="0 0 0"/>
      <parent link="delto_base_link"/>
      <child link="F1_01"/>
      <axis xyz="0.0 0.0 1.0"/>
      <limit effort="10.0" velocity="5.0" lower="-1.0472" upper="1.0472" />
      <dynamics damping="1.1" friction="1.1"/>
   </joint>

   <joint name = "F1M2" type = "revolute">
      <origin xyz="0.0 0.0 0.0" rpy="-3.1415926207728213 -1.570796290294655 0.0"/>
      <parent link="F1_01"/>
      <child link="F1_02"/>
      <axis xyz="0.0 0.0 1.0"/>
      <limit effort="10.0" velocity="5.0" lower="-1.76278" upper="1.76278" />
      <dynamics damping="1.1" friction="1.1"/>
   </joint>

   <joint name = "F1M3" type = "revolute">
      <origin xyz="0.02022 0.0 0.03136" rpy="-1.5707963295583207 -1.5707963267948966 0.0"/>
      <parent link="F1_02"/>
      <child link="F1_03"/>
      <axis xyz="0.0 0.0 1.0"/>
      <limit effort="10.0" velocity="5.0" lower="-0.15708" upper="2.53073" />
      <dynamics damping="1.1" friction="1.1"/>
   </joint>

   <joint name = "F1M4" type = "revolute">
      <origin xyz="0.0434 0.0 0.0" rpy="0 0 0"/>
      <parent link="F1_03"/>
      <child link="F1_04"/>
      <axis xyz="0.0 0.0 1.0"/>
      <limit effort="10.0" velocity="5.0" lower="-0.226893" upper="2.02458"/>
      <dynamics damping="1.1" friction="1.1"/>
   </joint>

   <joint name = "TIP1" type="fixed">
      <origin xyz="0.0 0.0 0.0" rpy="0 0 0"/>
      <parent link="F1_04"/>
      <child link="F1_TIP"/>
   </joint>

   <!-- FINGER 2-->

   <joint name = "F2M1" type = "revolute">
      <origin xyz="-0.01334 0.023 0.0" rpy="0 0 -3.14"/>
      <parent link="delto_base_link"/>
      <child link="F2_01"/>
      <axis xyz="0.0 0.0 1.0"/>
      <limit effort="10.0" velocity="5.0" lower="-1.91986" upper="0.139626" />
      <dynamics damping="1.1" friction="1.1"/>
   </joint>

   <joint name = "F2M2" type = "revolute">
      <origin xyz="0.0 0.0 0.0" rpy="-3.14 -1.57 0"/>
      <parent link="F2_01"/>
      <child link="F2_02"/>
      <axis xyz="0.0 0.0 1.0"/>
      <limit effort="10.0" velocity="5.0" lower="-1.76278" upper="1.76278" />
      <dynamics damping="1.1" friction="1.1"/>
   </joint>

   <joint name = "F2M3" type = "revolute">
      <origin xyz="0.02022 0.0 0.03136" rpy="-1.57 -1.57 0"/>
      <parent link="F2_02"/>
      <child link="F2_03"/>
      <axis xyz="0.0 0.0 1.0"/>
      <limit effort="10.0" velocity="5.0" lower="-0.15708" upper="2.53073" />
      <dynamics damping="1.1" friction="1.1"/>
   </joint>

   <joint name = "F2M4" type = "revolute">
      <origin xyz="0.0434 0.0 0.0" rpy="0 0 0"/>
      <parent link="F2_03"/>
      <child link="F2_04"/>
      <axis xyz="0.0434 0.0 1.0"/>
      <limit effort="10.0" velocity="5.0" lower="-0.226893" upper="2.02458" />
      <dynamics damping="1.1" friction="1.1"/>
   </joint>

   <joint name = "TIP2" type="fixed">
      <origin xyz="0.0 0.0 0.0" rpy="0 0 0"/>
      <parent link="F2_04"/>
      <child link="F2_TIP"/>
   </joint>

   <!-- FINGER 3-->   

   <joint name = "F3M1" type = "revolute">
      <origin xyz="-0.01334 -0.023 0.0" rpy="0 0 -3.14"/>
      <parent link="delto_base_link"/>
      <child link="F3_01"/>
      <axis xyz=".0 0.0 1.0"/>
      <limit effort="10.0" velocity="5.0" lower="-0.0872665" upper="2.00713" />
      <dynamics damping="1.1" friction="1.1"/>
   </joint>

   <joint name = "F3M2" type = "revolute">
      <origin xyz="0.0 0.0 0.0" rpy="-3.14 -1.57 0"/>
      <parent link="F3_01"/>
      <child link="F3_02"/>
      <axis xyz="0.0 0.0 1.0"/>
      <limit effort="10.0" velocity="5.0" lower="-1.76278" upper="1.76278" />
      <dynamics damping="1.1" friction="1.1"/>
   </joint>

   <joint name = "F3M3" type = "revolute">
      <origin xyz="0.02022 0.0 0.03136" rpy="-1.57 -1.57 0"/>
      <parent link="F3_02"/>
      <child link="F3_03"/>
      <axis xyz="0.0 0.0 1.0"/>
      <limit effort="10.0" velocity="5.0" lower="-0.15708" upper="2.53073" />
      <dynamics damping="1.1" friction="1.1"/>
   </joint>

   <joint name = "F3M4" type = "revolute">
      <origin xyz="0.0434 0.0 0.0" rpy="0 0 0"/>
      <parent link="F3_03"/>
      <child link="F3_04"/>
      <axis xyz="0.0 0.0 1.0"/>
      <limit effort="10.0" velocity="5.0" lower="-0.226893" upper="2.02458" />
      <dynamics damping="1.1" friction="1.1"/>
   </joint>

   <joint name = "TIP3" type="fixed">
      <origin xyz="0.0 0.0 0.0" rpy="0 0 0"/>
      <parent link="F3_04"/>
      <child link="F3_TIP"/>
   </joint>
  <!-- <link name="panda_hand">
    <visual>
      <geometry>
        <mesh filename="package://franka_description/meshes/visual/hand.dae"/>
      </geometry>
    </visual>
    <collision>
      <geometry>
        <mesh filename="package://franka_description/meshes/collision/hand.stl"/>
      </geometry>
    </collision>
  </link>
  <link name="panda_leftfinger">
    <visual>
      <geometry>
        <mesh filename="package://franka_description/meshes/visual/finger.dae"/>
      </geometry>
    </visual>
    <collision>
      <geometry>
        <mesh filename="package://franka_description/meshes/collision/finger.stl"/>
      </geometry>
    </collision>
  </link>
  <link name="panda_rightfinger">
    <visual>
      <origin rpy="0 0 3.14159265359" xyz="0 0 0"/>
      <geometry>
        <mesh filename="package://franka_description/meshes/visual/finger.dae"/>
      </geometry>
    </visual>
    <collision>
      <origin rpy="0 0 3.14159265359" xyz="0 0 0"/>
      <geometry>
        <mesh filename="package://franka_description/meshes/collision/finger.stl"/>
      </geometry>
    </collision>
  </link>
  <joint name="panda_finger_joint1" type="prismatic">
    <parent link="panda_hand"/>
    <child link="panda_leftfinger"/>
    <origin rpy="0 0 0" xyz="0 0 0.0584"/>
    <axis xyz="0 1 0"/>
    <limit effort="20" lower="0.0" upper="0.04" velocity="0.2"/>
  </joint>
  <joint name="panda_finger_joint2" type="prismatic">
    <parent link="panda_hand"/>
    <child link="panda_rightfinger"/>
    <origin rpy="0 0 0" xyz="0 0 0.0584"/>
    <axis xyz="0 -1 0"/>
    <limit effort="20" lower="0.0" upper="0.04" velocity="0.2"/>
    <mimic joint="panda_finger_joint1"/>
  </joint> -->
</robot>
