<?xml version="0.0" ?>
<robot name="delto_gripper_3f">
	<link name="delto_base_link">
		<inertial>
			<origin rpy="0.00001 0.00329 -0.00045" xyz="0.00045 -0.00000 -0.05219"/>
			<mass value="0.37000"/>
			<inertia ixx="0.00074" ixy="0" ixz="0" iyy="0.00074" iyz="0" izz="0.00038"/>
		</inertial>
		<visual>
			<origin rpy="0.00001 0.00329 -0.00045" xyz="0.00045 -0.00000 -0.05219"/>
			<geometry>
				<mesh filename="assets/hand/meshes/delto_base_link.stl" scale="1.00000 1.00000 1.00000"/>
			</geometry>
			<material name="mat_-1_0">
				<color rgba="0.19600 0.19600 0.19600 1.00000" />
			</material>
		</visual>
		<collision>
			<origin rpy="0.00001 0.00329 -0.00045" xyz="0.00045 -0.00000 -0.05219"/>
			<geometry>
				<mesh filename="assets/hand/meshes/delto_base_link.stl" scale="1.00000 1.00000 1.00000"/>
			</geometry>
		</collision>
	</link>
	<link name="F1_01">
		<inertial>
			<origin rpy="-0.17662 -0.00000 1.57079" xyz="0.00039 0.00000 -0.01400"/>
			<mass value="0.06100"/>
			<inertia ixx="0.00004" ixy="0" ixz="0" iyy="0.00003" iyz="0" izz="0.00001"/>
		</inertial>
		<visual>
			<origin rpy="-0.14439 0.00002 1.57092" xyz="0.00190 -0.00000 -0.02298"/>
			<geometry>
				<mesh filename="assets/hand/meshes/link_01.stl" scale="1.00000 1.00000 1.00000"/>
			</geometry>
			<material name="mat_0_0">
				<color rgba="0.19600 0.19600 0.19600 1.00000" />
			</material>
		</visual>
		<collision>
			<origin rpy="-0.14439 0.00002 1.57092" xyz="0.00190 -0.00000 -0.02298"/>
			<geometry>
				<mesh filename="assets/hand/meshes/link_01.stl" scale="1.00000 1.00000 1.00000"/>
			</geometry>
		</collision>
	</link>
	<link name="F1_02">
		<inertial>
			<origin rpy="-0.00369 0.31689 -0.00277" xyz="0.01000 0.00000 0.01600"/>
			<mass value="0.02500"/>
			<inertia ixx="0.00001" ixy="0" ixz="0" iyy="0.00002" iyz="0" izz="0.00001"/>
		</inertial>
		<visual>
			<origin rpy="-0.03118 0.37574 -0.02433" xyz="0.01032 0.00027 0.01359"/>
			<geometry>
				<mesh filename="assets/hand/meshes/link_02.stl" scale="1.00000 1.00000 1.00000"/>
			</geometry>
			<material name="mat_1_0">
				<color rgba="0.19600 0.19600 0.19600 1.00000" />
			</material>
		</visual>
		<collision>
			<origin rpy="-0.03118 0.37574 -0.02433" xyz="0.01032 0.00027 0.01359"/>
			<geometry>
				<mesh filename="assets/hand/meshes/link_02.stl" scale="1.00000 1.00000 1.00000"/>
			</geometry>
		</collision>
	</link>
	<link name="F1_03">
		<inertial>
			<origin rpy="1.56511 -0.00086 1.55626" xyz="0.01400 -0.00045 -0.00004"/>
			<mass value="0.05100"/>
			<inertia ixx="0.00003" ixy="0" ixz="0" iyy="0.00003" iyz="0" izz="0.00001"/>
		</inertial>
		<visual>
			<origin rpy="1.54055 -0.00236 1.59945" xyz="0.01903 -0.00076 0.00016"/>
			<geometry>
				<mesh filename="assets/hand/meshes/link_03.stl" scale="1.00000 1.00000 1.00000"/>
			</geometry>
			<material name="mat_2_0">
				<color rgba="0.19600 0.19600 0.19600 1.00000" />
			</material>
		</visual>
		<collision>
			<origin rpy="1.54055 -0.00236 1.59945" xyz="0.01903 -0.00076 0.00016"/>
			<geometry>
				<mesh filename="assets/hand/meshes/link_03.stl" scale="1.00000 1.00000 1.00000"/>
			</geometry>
		</collision>
	</link>
	<link name="F1_04">
		<inertial>
			<origin rpy="1.56685 -0.00087 1.58297" xyz="0.01200 -0.00023 -0.00005"/>
			<mass value="0.05800"/>
			<inertia ixx="0.00002" ixy="0" ixz="0" iyy="0.00002" iyz="0" izz="0.00001"/>
		</inertial>
		<visual>
			<origin rpy="1.57453 0.00360 1.66504" xyz="0.01199 -0.00077 -0.00001"/>
			<geometry>
				<mesh filename="assets/hand/meshes/link_04.stl" scale="1.00000 1.00000 1.00000"/>
			</geometry>
			<material name="mat_3_0">
				<color rgba="0.19600 0.19600 0.19600 1.00000" />
			</material>
		</visual>
		<collision>
			<origin rpy="1.57453 0.00360 1.66504" xyz="0.01199 -0.00077 -0.00001"/>
			<geometry>
				<mesh filename="assets/hand/meshes/link_04.stl" scale="1.00000 1.00000 1.00000"/>
			</geometry>
		</collision>
	</link>
	<link name="F1_TIP">
		<inertial>
			<origin rpy="1.57080 -0.00004 1.52109" xyz="0.04500 -0.00044 -0.00000"/>
			<mass value="0.01300"/>
			<inertia ixx="0.00000" ixy="0" ixz="0" iyy="0.00000" iyz="0" izz="0.00000"/>
		</inertial>
		<visual>
			<origin rpy="1.57087 -0.00001 1.52041" xyz="0.04496 -0.00042 0.00000"/>
			<geometry>
				<mesh filename="assets/hand/meshes/link_tip_high.stl" scale="1.00000 1.00000 1.00000"/>
			</geometry>
			<material name="mat_4_0">
				<color rgba="1.00000 1.00000 1.00000 1.00000" />
			</material>
		</visual>
		<collision>
			<origin rpy="1.57087 -0.00001 1.52041" xyz="0.04496 -0.00042 0.00000"/>
			<geometry>
				<mesh filename="assets/hand/meshes/link_tip_high.stl" scale="1.00000 1.00000 1.00000"/>
			</geometry>
		</collision>
	</link>
	<link name="F2_01">
		<inertial>
			<origin rpy="-0.17662 -0.00000 1.57079" xyz="0.00039 0.00000 -0.01400"/>
			<mass value="0.06100"/>
			<inertia ixx="0.00004" ixy="0" ixz="0" iyy="0.00003" iyz="0" izz="0.00001"/>
		</inertial>
		<visual>
			<origin rpy="-0.14439 0.00002 1.57092" xyz="0.00190 -0.00000 -0.02298"/>
			<geometry>
				<mesh filename="assets/hand/meshes/link_01.stl" scale="1.00000 1.00000 1.00000"/>
			</geometry>
			<material name="mat_5_0">
				<color rgba="0.19600 0.19600 0.19600 1.00000" />
			</material>
		</visual>
		<collision>
			<origin rpy="-0.14439 0.00002 1.57092" xyz="0.00190 -0.00000 -0.02298"/>
			<geometry>
				<mesh filename="assets/hand/meshes/link_01.stl" scale="1.00000 1.00000 1.00000"/>
			</geometry>
		</collision>
	</link>
	<link name="F2_02">
		<inertial>
			<origin rpy="-0.00369 0.31689 -0.00277" xyz="0.01000 0.00000 0.01600"/>
			<mass value="0.02500"/>
			<inertia ixx="0.00001" ixy="0" ixz="0" iyy="0.00002" iyz="0" izz="0.00001"/>
		</inertial>
		<visual>
			<origin rpy="-0.03118 0.37574 -0.02433" xyz="0.01032 0.00027 0.01359"/>
			<geometry>
				<mesh filename="assets/hand/meshes/link_02.stl" scale="1.00000 1.00000 1.00000"/>
			</geometry>
			<material name="mat_6_0">
				<color rgba="0.19600 0.19600 0.19600 1.00000" />
			</material>
		</visual>
		<collision>
			<origin rpy="-0.03118 0.37574 -0.02433" xyz="0.01032 0.00027 0.01359"/>
			<geometry>
				<mesh filename="assets/hand/meshes/link_02.stl" scale="1.00000 1.00000 1.00000"/>
			</geometry>
		</collision>
	</link>
	<link name="F2_03">
		<inertial>
			<origin rpy="1.56511 -0.00086 1.55626" xyz="0.01400 -0.00045 -0.00004"/>
			<mass value="0.05100"/>
			<inertia ixx="0.00003" ixy="0" ixz="0" iyy="0.00003" iyz="0" izz="0.00001"/>
		</inertial>
		<visual>
			<origin rpy="1.54055 -0.00236 1.59945" xyz="0.01903 -0.00076 0.00016"/>
			<geometry>
				<mesh filename="assets/hand/meshes/link_03.stl" scale="1.00000 1.00000 1.00000"/>
			</geometry>
			<material name="mat_7_0">
				<color rgba="0.19600 0.19600 0.19600 1.00000" />
			</material>
		</visual>
		<collision>
			<origin rpy="1.54055 -0.00236 1.59945" xyz="0.01903 -0.00076 0.00016"/>
			<geometry>
				<mesh filename="assets/hand/meshes/link_03.stl" scale="1.00000 1.00000 1.00000"/>
			</geometry>
		</collision>
	</link>
	<link name="F2_04">
		<inertial>
			<origin rpy="1.56685 -0.00087 1.58297" xyz="0.01200 -0.00023 -0.00005"/>
			<mass value="0.05800"/>
			<inertia ixx="0.00002" ixy="0" ixz="0" iyy="0.00002" iyz="0" izz="0.00001"/>
		</inertial>
		<visual>
			<origin rpy="1.57453 0.00360 1.66504" xyz="0.01199 -0.00077 -0.00001"/>
			<geometry>
				<mesh filename="assets/hand/meshes/link_04.stl" scale="1.00000 1.00000 1.00000"/>
			</geometry>
			<material name="mat_8_0">
				<color rgba="0.19600 0.19600 0.19600 1.00000" />
			</material>
		</visual>
		<collision>
			<origin rpy="1.57453 0.00360 1.66504" xyz="0.01199 -0.00077 -0.00001"/>
			<geometry>
				<mesh filename="assets/hand/meshes/link_04.stl" scale="1.00000 1.00000 1.00000"/>
			</geometry>
		</collision>
	</link>
	<link name="F2_TIP">
		<inertial>
			<origin rpy="1.57080 -0.00004 1.52109" xyz="0.04500 -0.00044 -0.00000"/>
			<mass value="0.01300"/>
			<inertia ixx="0.00000" ixy="0" ixz="0" iyy="0.00000" iyz="0" izz="0.00000"/>
		</inertial>
		<visual>
			<origin rpy="1.57087 -0.00001 1.52041" xyz="0.04496 -0.00042 0.00000"/>
			<geometry>
				<mesh filename="assets/hand/meshes/link_tip_high.stl" scale="1.00000 1.00000 1.00000"/>
			</geometry>
			<material name="mat_9_0">
				<color rgba="1.00000 1.00000 1.00000 1.00000" />
			</material>
		</visual>
		<collision>
			<origin rpy="1.57087 -0.00001 1.52041" xyz="0.04496 -0.00042 0.00000"/>
			<geometry>
				<mesh filename="assets/hand/meshes/link_tip_high.stl" scale="1.00000 1.00000 1.00000"/>
			</geometry>
		</collision>
	</link>
	<link name="F3_01">
		<inertial>
			<origin rpy="-0.17662 -0.00000 1.57079" xyz="0.00039 0.00000 -0.01400"/>
			<mass value="0.06100"/>
			<inertia ixx="0.00004" ixy="0" ixz="0" iyy="0.00003" iyz="0" izz="0.00001"/>
		</inertial>
		<visual>
			<origin rpy="-0.14439 0.00002 1.57092" xyz="0.00190 -0.00000 -0.02298"/>
			<geometry>
				<mesh filename="assets/hand/meshes/link_01.stl" scale="1.00000 1.00000 1.00000"/>
			</geometry>
			<material name="mat_10_0">
				<color rgba="0.19600 0.19600 0.19600 1.00000" />
			</material>
		</visual>
		<collision>
			<origin rpy="-0.14439 0.00002 1.57092" xyz="0.00190 -0.00000 -0.02298"/>
			<geometry>
				<mesh filename="assets/hand/meshes/link_01.stl" scale="1.00000 1.00000 1.00000"/>
			</geometry>
		</collision>
	</link>
	<link name="F3_02">
		<inertial>
			<origin rpy="-0.00369 0.31689 -0.00277" xyz="0.01000 0.00000 0.01600"/>
			<mass value="0.02500"/>
			<inertia ixx="0.00001" ixy="0" ixz="0" iyy="0.00002" iyz="0" izz="0.00001"/>
		</inertial>
		<visual>
			<origin rpy="-0.03118 0.37574 -0.02433" xyz="0.01032 0.00027 0.01359"/>
			<geometry>
				<mesh filename="assets/hand/meshes/link_02.stl" scale="1.00000 1.00000 1.00000"/>
			</geometry>
			<material name="mat_11_0">
				<color rgba="0.19600 0.19600 0.19600 1.00000" />
			</material>
		</visual>
		<collision>
			<origin rpy="-0.03118 0.37574 -0.02433" xyz="0.01032 0.00027 0.01359"/>
			<geometry>
				<mesh filename="assets/hand/meshes/link_02.stl" scale="1.00000 1.00000 1.00000"/>
			</geometry>
		</collision>
	</link>
	<link name="F3_03">
		<inertial>
			<origin rpy="1.56511 -0.00086 1.55626" xyz="0.01400 -0.00045 -0.00004"/>
			<mass value="0.05100"/>
			<inertia ixx="0.00003" ixy="0" ixz="0" iyy="0.00003" iyz="0" izz="0.00001"/>
		</inertial>
		<visual>
			<origin rpy="1.54055 -0.00236 1.59945" xyz="0.01903 -0.00076 0.00016"/>
			<geometry>
				<mesh filename="assets/hand/meshes/link_03.stl" scale="1.00000 1.00000 1.00000"/>
			</geometry>
			<material name="mat_12_0">
				<color rgba="0.19600 0.19600 0.19600 1.00000" />
			</material>
		</visual>
		<collision>
			<origin rpy="1.54055 -0.00236 1.59945" xyz="0.01903 -0.00076 0.00016"/>
			<geometry>
				<mesh filename="assets/hand/meshes/link_03.stl" scale="1.00000 1.00000 1.00000"/>
			</geometry>
		</collision>
	</link>
	<link name="F3_04">
		<inertial>
			<origin rpy="1.56685 -0.00087 1.58297" xyz="0.01200 -0.00023 -0.00005"/>
			<mass value="0.05800"/>
			<inertia ixx="0.00002" ixy="0" ixz="0" iyy="0.00002" iyz="0" izz="0.00001"/>
		</inertial>
		<visual>
			<origin rpy="1.57453 0.00360 1.66504" xyz="0.01199 -0.00077 -0.00001"/>
			<geometry>
				<mesh filename="assets/hand/meshes/link_04.stl" scale="1.00000 1.00000 1.00000"/>
			</geometry>
			<material name="mat_13_0">
				<color rgba="0.19600 0.19600 0.19600 1.00000" />
			</material>
		</visual>
		<collision>
			<origin rpy="1.57453 0.00360 1.66504" xyz="0.01199 -0.00077 -0.00001"/>
			<geometry>
				<mesh filename="assets/hand/meshes/link_04.stl" scale="1.00000 1.00000 1.00000"/>
			</geometry>
		</collision>
	</link>
	<link name="F3_TIP">
		<inertial>
			<origin rpy="1.57080 -0.00004 1.52109" xyz="0.04500 -0.00044 -0.00000"/>
			<mass value="0.01300"/>
			<inertia ixx="0.00000" ixy="0" ixz="0" iyy="0.00000" iyz="0" izz="0.00000"/>
		</inertial>
		<visual>
			<origin rpy="1.57087 -0.00001 1.52041" xyz="0.04496 -0.00042 0.00000"/>
			<geometry>
				<mesh filename="assets/hand/meshes/link_tip_high.stl" scale="1.00000 1.00000 1.00000"/>
			</geometry>
			<material name="mat_14_0">
				<color rgba="1.00000 1.00000 1.00000 1.00000" />
			</material>
		</visual>
		<collision>
			<origin rpy="1.57087 -0.00001 1.52041" xyz="0.04496 -0.00042 0.00000"/>
			<geometry>
				<mesh filename="assets/hand/meshes/link_tip_high.stl" scale="1.00000 1.00000 1.00000"/>
			</geometry>
		</collision>
	</link>
	<link name="panda_link0">
		<inertial>
			<origin rpy="0.00000 -0.00000 0.00000" xyz="0.00000 0.00000 0.00000"/>
			<mass value="2.90000"/>
			<inertia ixx="0.01437" ixy="0" ixz="0" iyy="0.01812" iyz="0" izz="0.02218"/>
		</inertial>
		<visual>
			<origin rpy="0.00000 -0.00000 0.00000" xyz="0.00000 0.00000 0.00000"/>
			<geometry>
				<mesh filename="assets/arm/meshes/collision/link0.obj" scale="1.00000 1.00000 1.00000"/>
			</geometry>
			<material name="mat_-1_0">
				<color rgba="1.00000 1.00000 1.00000 1.00000" />
			</material>
		</visual>
		<collision>
			<origin rpy="0.00000 -0.00000 0.00000" xyz="0.00000 0.00000 0.00000"/>
			<geometry>
				<mesh filename="assets/arm/meshes/collision/link0.obj" scale="1.00000 1.00000 1.00000"/>
			</geometry>
		</collision>
	</link>
	<link name="panda_link1">
		<inertial>
			<origin rpy="0.00000 -0.00000 0.00000" xyz="0.00000 -0.04000 -0.05000"/>
			<mass value="2.70000"/>
			<inertia ixx="0.02297" ixy="0" ixz="0" iyy="0.01777" iyz="0" izz="0.01148"/>
		</inertial>
		<visual>
			<origin rpy="0.00000 -0.00000 0.00000" xyz="0.00000 0.00000 0.00000"/>
			<geometry>
				<mesh filename="assets/arm/meshes/visual/link1.obj" scale="1.00000 1.00000 1.00000"/>
			</geometry>
			<material name="mat_0_0">
				<color rgba="1.00000 1.00000 1.00000 1.00000" />
			</material>
		</visual>
		<collision>
			<origin rpy="0.00000 -0.00000 0.00000" xyz="0.00000 0.00000 0.00000"/>
			<geometry>
				<mesh filename="assets/arm/meshes/collision/link1.obj" scale="1.00000 1.00000 1.00000"/>
			</geometry>
		</collision>
	</link>
	<link name="panda_link2">
		<inertial>
			<origin rpy="0.00000 -0.00000 0.00000" xyz="0.00000 -0.04000 0.06000"/>
			<mass value="2.73000"/>
			<inertia ixx="0.02349" ixy="0" ixz="0" iyy="0.01161" iyz="0" izz="0.01823"/>
		</inertial>
		<visual>
			<origin rpy="0.00000 -0.00000 0.00000" xyz="0.00000 0.00000 0.00000"/>
			<geometry>
				<mesh filename="assets/arm/meshes/visual/link2.obj" scale="1.00000 1.00000 1.00000"/>
			</geometry>
			<material name="mat_1_0">
				<color rgba="1.00000 1.00000 1.00000 1.00000" />
			</material>
		</visual>
		<collision>
			<origin rpy="0.00000 -0.00000 0.00000" xyz="0.00000 0.00000 0.00000"/>
			<geometry>
				<mesh filename="assets/arm/meshes/collision/link2.obj" scale="1.00000 1.00000 1.00000"/>
			</geometry>
		</collision>
	</link>
	<link name="panda_link3">
		<inertial>
			<origin rpy="0.00000 -0.00000 0.00000" xyz="0.01000 0.01000 -0.05000"/>
			<mass value="2.04000"/>
			<inertia ixx="0.01092" ixy="0" ixz="0" iyy="0.01258" iyz="0" izz="0.01197"/>
		</inertial>
		<visual>
			<origin rpy="0.00000 -0.00000 0.00000" xyz="0.00000 0.00000 0.00000"/>
			<geometry>
				<mesh filename="assets/arm/meshes/visual/link3.obj" scale="1.00000 1.00000 1.00000"/>
			</geometry>
			<material name="mat_2_0">
				<color rgba="1.00000 1.00000 1.00000 1.00000" />
			</material>
		</visual>
		<collision>
			<origin rpy="0.00000 -0.00000 0.00000" xyz="0.00000 0.00000 0.00000"/>
			<geometry>
				<mesh filename="assets/arm/meshes/collision/link3.obj" scale="1.00000 1.00000 1.00000"/>
			</geometry>
		</collision>
	</link>
	<link name="panda_link4">
		<inertial>
			<origin rpy="0.00000 -0.00000 0.00000" xyz="-0.03000 0.03000 0.02000"/>
			<mass value="2.08000"/>
			<inertia ixx="0.01134" ixy="0" ixz="0" iyy="0.01225" iyz="0" izz="0.01306"/>
		</inertial>
		<visual>
			<origin rpy="0.00000 -0.00000 0.00000" xyz="0.00000 0.00000 0.00000"/>
			<geometry>
				<mesh filename="assets/arm/meshes/visual/link4.obj" scale="1.00000 1.00000 1.00000"/>
			</geometry>
			<material name="mat_3_0">
				<color rgba="1.00000 1.00000 1.00000 1.00000" />
			</material>
		</visual>
		<collision>
			<origin rpy="0.00000 -0.00000 0.00000" xyz="0.00000 0.00000 0.00000"/>
			<geometry>
				<mesh filename="assets/arm/meshes/collision/link4.obj" scale="1.00000 1.00000 1.00000"/>
			</geometry>
		</collision>
	</link>
	<link name="panda_link5">
		<inertial>
			<origin rpy="0.00000 -0.00000 0.00000" xyz="0.00000 0.04000 -0.12000"/>
			<mass value="3.00000"/>
			<inertia ixx="0.03568" ixy="0" ixz="0" iyy="0.02985" iyz="0" izz="0.01280"/>
		</inertial>
		<visual>
			<origin rpy="0.00000 -0.00000 0.00000" xyz="0.00000 0.00000 0.00000"/>
			<geometry>
				<mesh filename="assets/arm/meshes/visual/link5.obj" scale="1.00000 1.00000 1.00000"/>
			</geometry>
			<material name="mat_4_0">
				<color rgba="1.00000 1.00000 1.00000 1.00000" />
			</material>
		</visual>
		<collision>
			<origin rpy="0.00000 -0.00000 0.00000" xyz="0.00000 0.00000 0.00000"/>
			<geometry>
				<mesh filename="assets/arm/meshes/collision/link5.obj" scale="1.00000 1.00000 1.00000"/>
			</geometry>
		</collision>
	</link>
	<link name="panda_link6">
		<inertial>
			<origin rpy="0.00000 -0.00000 0.00000" xyz="0.04000 0.00000 0.00000"/>
			<mass value="1.30000"/>
			<inertia ixx="0.00000" ixy="0" ixz="0" iyy="0.00000" iyz="0" izz="0.00000"/>
		</inertial>
		<visual>
			<origin rpy="0.00000 -0.00000 0.00000" xyz="0.00000 0.00000 0.00000"/>
			<geometry>
				<mesh filename="assets/arm/meshes/visual/link6.obj" scale="1.00000 1.00000 1.00000"/>
			</geometry>
			<material name="mat_5_0">
				<color rgba="1.00000 1.00000 1.00000 1.00000" />
			</material>
		</visual>
		<collision>
			<origin rpy="0.00000 -0.00000 0.00000" xyz="0.00000 0.00000 0.00000"/>
			<geometry>
				<mesh filename="assets/arm/meshes/collision/link6.obj" scale="1.00000 1.00000 1.00000"/>
			</geometry>
		</collision>
	</link>
	<link name="panda_link7">
		<inertial>
			<origin rpy="0.00000 -0.00000 0.00000" xyz="0.00000 0.00000 0.08000"/>
			<mass value="0.20000"/>
			<inertia ixx="0.00036" ixy="0" ixz="0" iyy="0.00036" iyz="0" izz="0.00059"/>
		</inertial>
		<visual>
			<origin rpy="0.00000 -0.00000 0.00000" xyz="0.00000 0.00000 0.00000"/>
			<geometry>
				<mesh filename="assets/arm/meshes/collision/link7.obj" scale="1.00000 1.00000 1.00000"/>
			</geometry>
			<material name="mat_6_0">
				<color rgba="1.00000 1.00000 1.00000 1.00000" />
			</material>
		</visual>
		<collision>
			<origin rpy="0.00000 -0.00000 0.00000" xyz="0.00000 0.00000 0.00000"/>
			<geometry>
				<mesh filename="assets/arm/meshes/collision/link7.obj" scale="1.00000 1.00000 1.00000"/>
			</geometry>
		</collision>
	</link>
	<link name="panda_link8">
		<inertial>
			<origin rpy="0.00000 -0.00000 0.00000" xyz="0.00000 0.00000 0.00000"/>
			<mass value="0.00000"/>
			<inertia ixx="0.00000" ixy="0" ixz="0" iyy="0.00000" iyz="0" izz="0.00000"/>
		</inertial>
	</link>
	<link name="panda_hand">
		<inertial>
			<origin rpy="0.00000 -0.00000 0.00000" xyz="0.00000 0.00000 0.04000"/>
			<mass value="0.81000"/>
			<inertia ixx="0.00000" ixy="0" ixz="0" iyy="0.00000" iyz="0" izz="0.00000"/>
		</inertial>
	</link>
	<link name="panda_grasptarget">
		<inertial>
			<origin rpy="0.00000 -0.00000 0.00000" xyz="0.00000 0.00000 0.00000"/>
			<mass value="0.00000"/>
			<inertia ixx="0.00000" ixy="0" ixz="0" iyy="0.00000" iyz="0" izz="0.00000"/>
		</inertial>
	</link>
	<joint name="F1M1" type="revolute">
		<parent link="delto_base_link"/>
		<child link="F1_01"/>
		<limit effort="10.00000" lower="-1.04720" upper="1.04720" velocity="5.00000"/>
		<dynamics damping="1.0" friction="0.0001"/>
		<origin rpy="0.00000 0.00000 -0.00000" xyz="0.02650 -0.00000 0.00000"/>
		<axis xyz="0.00000 -0.17571 0.98444"/>
	</joint>
	<joint name="F1M2" type="revolute">
		<parent link="F1_01"/>
		<child link="F1_02"/>
		<limit effort="10.00000" lower="-1.76278" upper="1.76278" velocity="5.00000"/>
		<dynamics damping="1.0" friction="0.0001"/>
		<origin rpy="0.00000 -1.57080 3.14159" xyz="0.00000 0.00000 -0.00000"/>
		<axis xyz="-0.31161 -0.00351 0.95020"/>
	</joint>
	<joint name="F1M3" type="revolute">
		<parent link="F1_02"/>
		<child link="F1_03"/>
		<limit effort="10.00000" lower="-0.15708" upper="2.53073" velocity="5.00000"/>
		<dynamics damping="1.0" friction="0.0001"/>
		<origin rpy="0.00000 -1.57080 4.71239" xyz="0.02022 -0.00000 0.03136"/>
		<axis xyz="0.00086 0.99998 0.00569"/>
	</joint>
	<joint name="F1M4" type="revolute">
		<parent link="F1_03"/>
		<child link="F1_04"/>
		<limit effort="10.00000" lower="-0.22689" upper="2.02458" velocity="5.00000"/>
		<dynamics damping="1.0" friction="0.0001"/>
		<origin rpy="-0.00000 -0.00000 -0.00000" xyz="0.04340 -0.00000 0.00000"/>
		<axis xyz="0.00087 0.99999 0.00395"/>
	</joint>
	<joint name="TIP1" type="fixed">
		<parent link="F1_04"/>
		<child link="F1_TIP"/>
		<dynamics damping="1.0" friction="0.0001"/>
		<origin rpy="0.00000 -0.00000 0.00000" xyz="0.00000 0.00000 0.00000"/>
		<axis xyz="0.00000 0.00000 0.00000"/>
	</joint>
	<joint name="F2M1" type="revolute">
		<parent link="delto_base_link"/>
		<child link="F2_01"/>
		<limit effort="10.00000" lower="-1.91986" upper="0.13963" velocity="5.00000"/>
		<dynamics damping="1.0" friction="0.0001"/>
		<origin rpy="0.00000 -0.00000 -3.14000" xyz="-0.01334 0.02300 0.00000"/>
		<axis xyz="0.00000 -0.17571 0.98444"/>
	</joint>
	<joint name="F2M2" type="revolute">
		<parent link="F2_01"/>
		<child link="F2_02"/>
		<limit effort="10.00000" lower="-1.76278" upper="1.76278" velocity="5.00000"/>
		<dynamics damping="1.0" friction="0.0001"/>
		<origin rpy="0.00000 -1.57080 3.14318" xyz="0.00000 0.00000 -0.00000"/>
		<axis xyz="-0.31161 -0.00351 0.95020"/>
	</joint>
	<joint name="F2M3" type="revolute">
		<parent link="F2_02"/>
		<child link="F2_03"/>
		<limit effort="10.00000" lower="-0.15708" upper="2.53073" velocity="5.00000"/>
		<dynamics damping="1.0" friction="0.0001"/>
		<origin rpy="0.00000 -1.57080 -1.57080" xyz="0.02022 -0.00000 0.03136"/>
		<axis xyz="0.00086 0.99998 0.00569"/>
	</joint>
	<joint name="F2M4" type="revolute">
		<parent link="F2_03"/>
		<child link="F2_04"/>
		<limit effort="10.00000" lower="-0.22689" upper="2.02458" velocity="5.00000"/>
		<dynamics damping="1.0" friction="0.0001"/>
		<origin rpy="-0.00000 -0.00000 -0.00000" xyz="0.04340 -0.00000 0.00000"/>
		<axis xyz="0.00034 0.99982 0.04734"/>
	</joint>
	<joint name="TIP2" type="fixed">
		<parent link="F2_04"/>
		<child link="F2_TIP"/>
		<dynamics damping="1.0" friction="0.0001"/>
		<origin rpy="0.00000 -0.00000 0.00000" xyz="0.00000 0.00000 0.00000"/>
		<axis xyz="0.00000 0.00000 0.00000"/>
	</joint>
	<joint name="F3M1" type="revolute">
		<parent link="delto_base_link"/>
		<child link="F3_01"/>
		<limit effort="10.00000" lower="-0.08727" upper="2.00713" velocity="5.00000"/>
		<dynamics damping="1.0" friction="0.0001"/>
		<origin rpy="0.00000 -0.00000 -3.14000" xyz="-0.01334 -0.02300 0.00000"/>
		<axis xyz="0.00000 -0.17571 0.98444"/>
	</joint>
	<joint name="F3M2" type="revolute">
		<parent link="F3_01"/>
		<child link="F3_02"/>
		<limit effort="10.00000" lower="-1.76278" upper="1.76278" velocity="5.00000"/>
		<dynamics damping="1.0" friction="0.0001"/>
		<origin rpy="0.00000 -1.57080 3.14318" xyz="0.00000 0.00000 -0.00000"/>
		<axis xyz="-0.31161 -0.00351 0.95020"/>
	</joint>
	<joint name="F3M3" type="revolute">
		<parent link="F3_02"/>
		<child link="F3_03"/>
		<limit effort="10.00000" lower="-0.15708" upper="2.53073" velocity="5.00000"/>
		<dynamics damping="1.0" friction="0.0001"/>
		<origin rpy="0.00000 -1.57080 -1.57080" xyz="0.02022 -0.00000 0.03136"/>
		<axis xyz="0.00086 0.99998 0.00569"/>
	</joint>
	<joint name="F3M4" type="revolute">
		<parent link="F3_03"/>
		<child link="F3_04"/>
		<limit effort="10.00000" lower="-0.22689" upper="2.02458" velocity="5.00000"/>
		<dynamics damping="1.0" friction="0.0001"/>
		<origin rpy="-0.00000 -0.00000 -0.00000" xyz="0.04340 -0.00000 0.00000"/>
		<axis xyz="0.00087 0.99999 0.00395"/>
	</joint>
	<joint name="TIP3" type="fixed">
		<parent link="F3_04"/>
		<child link="F3_TIP"/>
		<dynamics damping="1.0" friction="0.0001"/>
		<origin rpy="0.00000 -0.00000 0.00000" xyz="0.00000 0.00000 0.00000"/>
		<axis xyz="0.00000 0.00000 0.00000"/>
	</joint>
	<joint name="joint_dummy1" type="fixed">
		<parent link="delto_base_link"/>
		<child link="panda_link0"/>
		<dynamics damping="1.0" friction="0.0001"/>
		<origin rpy="0.00000 0.00000 0.00000" xyz="0.00000 0.00000 0.00000"/>
		<axis xyz="0.00000 0.00000 1.00000"/>
	</joint>
	<joint name="panda_joint1" type="revolute">
		<parent link="panda_link0"/>
		<child link="panda_link1"/>
		<limit effort="87.00000" lower="-2.96710" upper="2.96710" velocity="2.17500"/>
		<dynamics damping="1.0" friction="0.0001"/>
		<origin rpy="0.00000 -0.00000 0.00000" xyz="0.00000 0.00000 0.33300"/>
		<axis xyz="0.00000 0.00000 1.00000"/>
	</joint>
	<joint name="panda_joint2" type="revolute">
		<parent link="panda_link1"/>
		<child link="panda_link2"/>
		<limit effort="87.00000" lower="-1.83260" upper="1.83260" velocity="2.17500"/>
		<dynamics damping="1.0" friction="0.0001"/>
		<origin rpy="-1.57080 0.00000 0.00000" xyz="0.00000 0.00000 0.00000"/>
		<axis xyz="0.00000 0.00000 1.00000"/>
	</joint>
	<joint name="panda_joint3" type="revolute">
		<parent link="panda_link2"/>
		<child link="panda_link3"/>
		<limit effort="87.00000" lower="-2.96710" upper="2.96710" velocity="2.17500"/>
		<dynamics damping="1.0" friction="0.0001"/>
		<origin rpy="1.57080 -0.00000 0.00000" xyz="0.00000 -0.31600 0.00000"/>
		<axis xyz="0.00000 0.00000 1.00000"/>
	</joint>
	<joint name="panda_joint4" type="revolute">
		<parent link="panda_link3"/>
		<child link="panda_link4"/>
		<limit effort="87.00000" lower="-3.14160" upper="0.00000" velocity="2.17500"/>
		<dynamics damping="1.0" friction="0.0001"/>
		<origin rpy="1.57080 -0.00000 0.00000" xyz="0.08250 0.00000 0.00000"/>
		<axis xyz="0.00000 0.00000 1.00000"/>
	</joint>
	<joint name="panda_joint5" type="revolute">
		<parent link="panda_link4"/>
		<child link="panda_link5"/>
		<limit effort="12.00000" lower="-2.96710" upper="2.96710" velocity="2.61000"/>
		<dynamics damping="1.0" friction="0.0001"/>
		<origin rpy="-1.57080 0.00000 0.00000" xyz="-0.08250 0.38400 0.00000"/>
		<axis xyz="0.00000 0.00000 1.00000"/>
	</joint>
	<joint name="panda_joint6" type="revolute">
		<parent link="panda_link5"/>
		<child link="panda_link6"/>
		<limit effort="12.00000" lower="-0.08730" upper="3.82230" velocity="2.61000"/>
		<dynamics damping="1.0" friction="0.0001"/>
		<origin rpy="1.57080 -0.00000 0.00000" xyz="0.00000 0.00000 0.00000"/>
		<axis xyz="0.00000 0.00000 1.00000"/>
	</joint>
	<joint name="panda_joint7" type="revolute">
		<parent link="panda_link6"/>
		<child link="panda_link7"/>
		<limit effort="12.00000" lower="-2.96710" upper="2.96710" velocity="2.61000"/>
		<dynamics damping="1.0" friction="0.0001"/>
		<origin rpy="1.57080 -0.00000 0.00000" xyz="0.08800 0.00000 0.00000"/>
		<axis xyz="0.00000 0.00000 1.00000"/>
	</joint>
	<joint name="panda_joint8" type="fixed">
		<parent link="panda_link7"/>
		<child link="panda_link8"/>
		<dynamics damping="1.0" friction="0.0001"/>
		<origin rpy="0.00000 -0.00000 0.00000" xyz="0.00000 0.00000 0.10700"/>
		<axis xyz="0.00000 0.00000 0.00000"/>
	</joint>
	<joint name="panda_hand_joint" type="fixed">
		<parent link="panda_link8"/>
		<child link="panda_hand"/>
		<dynamics damping="1.0" friction="0.0001"/>
		<origin rpy="0.00000 0.00000 -0.78540" xyz="0.00000 0.00000 0.00000"/>
		<axis xyz="0.00000 0.00000 0.00000"/>
	</joint>
	<joint name="panda_grasptarget_hand" type="fixed">
		<parent link="panda_hand"/>
		<child link="panda_grasptarget"/>
		<dynamics damping="1.0" friction="0.0001"/>
		<origin rpy="0.00000 -0.00000 0.00000" xyz="0.00000 0.00000 0.06000"/>
		<axis xyz="0.00000 0.00000 0.00000"/>
	</joint>
</robot>
